Workbook

Sheet Dashboard
B2: Comportamiento de las Personas en su Día de Cumpleaños
B4: Panel analítico · Base de datos Costa Rica · 600 perfiles · hábitos de gasto, canal de pago y preferencias por cumpleaños
B6: PERFILES ANALIZADOS | E6: EDAD PROMEDIO | H6: GASTO PROMEDIO (₡) | K6: MES CON MÁS CUMPLEAÑOS
B7: =COUNTA(Datos!$A$2:$A$601) -> 600 | E7: =AVERAGE(Datos!$F$2:$F$601) -> 42.613333 | H7: =AVERAGE(Datos!$M$2:$M$601) -> 173962.95 | K7: =INDEX(Resumen!$B$4:$B$15,MATCH(MAX(Resumen!$C$4:$C$15),Resumen!$C$4:$C$15,0)) -> Noviembre

Sheet Datos
A1: ID | B1: Nombre | C1: Primer Apellido | D1: Segundo Apellido | E1: Género | F1: Edad | G1: Mes de Cumpleaños | H1: Día de Cumpleaños | I1: Signo Zodiacal | J1: Provincia | K1: Cantón | L1: Conducta de Gasto | M1: Monto Promedio de Compra (₡) | N1: Frecuencia de Compra | O1: Momento del Día Preferido | P1: Categoría de Preferencia | Q1: Marca Preferida | R1: Método de Pago Preferido | S1: Grupo Edad
A2: 1 | B2: Ana | C2: Blanco | D2: Zúñiga | E2: Femenino | F2: 24 | G2: Abril | H2: 8 | I2: Aries | J2: Alajuela | K2: Sarchí | L2: Ahorrador | M2: 208720 | N2: Semanal | O2: Mañana | P2: Educación | Q2: UCR | R2: Tarjeta de débito | S2: =IF(F2<25,"18-24",IF(F2<35,"25-34",IF(F2<45,"35-44",IF(F2<55,"45-54","55-65")))) -> 18-24
A3: 2 | B3: Yolanda | C3: Duarte | D3: González | E3: Femenino | F3: 62 | G3: Septiembre | H3: 7 | I3: Virgo | J3: Puntarenas | K3: Garabito | L3: Gastador en ocasiones especiales | M3: 81052 | N3: Mensual | O3: Mañana | P3: Educación | Q3: Udemy | R3: Tarjeta de débito | S3: =IF(F3<25,"18-24",IF(F3<35,"25-34",IF(F3<45,"35-44",IF(F3<55,"45-54","55-65")))) -> 55-65
A4: 3 | B4: Gerardo | C4: Zúñiga | D4: Sánchez | E4: Masculino | F4: 23 | G4: Abril | H4: 25 | I4: Tauro | J4: Cartago | K4: Paraíso | L4: Planificador | M4: 128848 | N4: Diaria | O4: Tarde | P4: Entretenimiento/streaming | Q4: Netflix | R4: Tarjeta de crédito | S4: =IF(F4<25,"18-24",IF(F4<35,"25-34",IF(F4<45,"35-44",IF(F4<55,"45-54","55-65")))) -> 18-24
A5: 4 | B5: Freddy | C5: Solano | D5: Cruz | E5: Masculino | F5: 54 | G5: Febrero | H5: 18 | I5: Acuario | J5: Cartago | K5: Alvarado | L5: Gastador impulsivo | M5: 20809 | N5: Mensual | O5: Mañana | P5: Viajes | Q5: Avianca | R5: Tarjeta de débito | S5: =IF(F5<25,"18-24",IF(F5<35,"25-34",IF(F5<45,"35-44",IF(F5<55,"45-54","55-65")))) -> 45-54
A6: 5 | B6: Carolina | C6: Zúñiga | D6: Elizondo | E6: Femenino | F6: 41 | G6: Noviembre | H6: 27 | I6: Sagitario | J6: Cartago | K6: La Unión | L6: Ahorrador | M6: 236210 | N6: Diaria | O6: Noche | P6: Deportes y fitness | Q6: Adidas | R6: Tarjeta de débito | S6: =IF(F6<25,"18-24",IF(F6<35,"25-34",IF(F6<45,"35-44",IF(F6<55,"45-54","55-65")))) -> 35-44
A7: 6 | B7: Fiorella | C7: Elizondo | D7: Cruz | E7: Femenino | F7: 32 | G7: Mayo | H7: 30 | I7: Géminis | J7: Puntarenas | K7: Parrita | L7: Ahorrador | M7: 84022 | N7: Mensual | O7: Tarde | P7: Deportes y fitness | Q7: Nike | R7: SINPE Móvil | S7: =IF(F7<25,"18-24",IF(F7<35,"25-34",IF(F7<45,"35-44",IF(F7<55,"45-54","55-65")))) -> 25-34
A8: 7 | B8: Yendry | C8: Obando | D8: Monge | E8: Femenino | F8: 43 | G8: Junio | H8: 7 | I8: Géminis | J8: Puntarenas | K8: Coto Brus | L8: Gastador impulsivo | M8: 96384 | N8: Diaria | O8: Noche | P8: Hogar y decoración | Q8: Gollo | R8: SINPE Móvil | S8: =IF(F8<25,"18-24",IF(F8<35,"25-34",IF(F8<45,"35-44",IF(F8<55,"45-54","55-65")))) -> 35-44
A9: 8 | B9: Eddy | C9: Gómez | D9: Barrantes | E9: Masculino | F9: 23 | G9: Abril | H9: 5 | I9: Aries | J9: Guanacaste | K9: Tilarán | L9: Gastador impulsivo | M9: 57730 | N9: Ocasional | O9: Noche | P9: Tecnología | Q9: Samsung | R9: Tarjeta de crédito | S9: =IF(F9<25,"18-24",IF(F9<35,"25-34",IF(F9<45,"35-44",IF(F9<55,"45-54","55-65")))) -> 18-24
A10: 9 | B10: Rodrigo | C10: Duarte | D10: Elizondo | E10: Masculino | F10: 61 | G10: Septiembre | H10: 9 | I10: Virgo | J10: Guanacaste | K10: Liberia | L10: Planificador | M10: 264053 | N10: Semanal | O10: Tarde | P10: Moda y ropa | Q10: Aldo | R10: Efectivo | S10: =IF(F10<25,"18-24",IF(F10<35,"25-34",IF(F10<45,"35-44",IF(F10<55,"45-54","55-65")))) -> 55-65
A11: 10 | B11: Ivannia | C11: Rodríguez | D11: Acuña | E11: Femenino | F11: 50 | G11: Diciembre | H11: 9 | I11: Sagitario | J11: Guanacaste | K11: Santa Cruz | L11: Gastador en ocasiones especiales | M11: 295376 | N11: Diaria | O11: Mañana | P11: Moda y ropa | Q11: Adidas | R11: Tarjeta de débito | S11: =IF(F11<25,"18-24",IF(F11<35,"25-34",IF(F11<45,"35-44",IF(F11<55,"45-54","55-65")))) -> 45-54
A12: 11 | B12: Fernando | C12: Loría | D12: Delgado | E12: Masculino | F12: 49 | G12: Septiembre | H12: 30 | I12: Libra | J12: San José | K12: Vázquez de Coronado | L12: Planificador | M12: 325539 | N12: Quincenal | O12: Mañana | P12: Tecnología | Q12: Samsung | R12: Tarjeta de débito | S12: =IF(F12<25,"18-24",IF(F12<35,"25-34",IF(F12<45,"35-44",IF(F12<55,"45-54","55-65")))) -> 45-54
A13: 12 | B13: Marcela | C13: Acuña | D13: Ureña | E13: Femenino | F13: 26 | G13: Febrero | H13: 25 | I13: Piscis | J13: Guanacaste | K13: Santa Cruz | L13: Gastador en ocasiones especiales | M13: 61969 | N13: Diaria | O13: Tarde | P13: Hogar y decoración | Q13: Jumbo | R13: Tarjeta de débito | S13: =IF(F13<25,"18-24",IF(F13<35,"25-34",IF(F13<45,"35-44",IF(F13<55,"45-54","55-65")))) -> 25-34
... A601: 600 | B601: Tatiana | C601: Umaña | D601: Vega | E601: Femenino | F601: 29 | G601: Marzo | H601: 2 | I601: Piscis | J601: Guanacaste | K601: Cañas | L601: Ahorrador | M601: 107818 | N601: Mensual | O601: Mañana | P601: Tecnología | Q601: Samsung | R601: Efectivo | S601: =IF(F601<25,"18-24",IF(F601<35,"25-34",IF(F601<45,"35-44",IF(F601<55,"45-54","55-65")))) -> 25-34

Sheet Resumen
B2: 1. Nacimientos por mes | F2: 2. Grupo de edad | J2: 3. Provincia
B3: Categoría | C3: Cantidad | D3: Gasto Prom. (₡) | F3: Categoría | G3: Cantidad | H3: Gasto Prom. (₡) | J3: Categoría | K3: Cantidad | L3: Gasto Prom. (₡)
B4: Enero | C4: =COUNTIF(Datos!$G$2:$G$601,B4) -> 45 | D4: =IFERROR(AVERAGEIF(Datos!$G$2:$G$601,B4,Datos!$M$2:$M$601),0) -> 178318.04 | F4: 18-24 | G4: =COUNTIF(Datos!$S$2:$S$601,F4) -> 70 | H4: =IFERROR(AVERAGEIF(Datos!$S$2:$S$601,F4,Datos!$M$2:$M$601),0) -> 159406.66 | J4: Alajuela | K4: =COUNTIF(Datos!$J$2:$J$601,J4) -> 80 | L4: =IFERROR(AVERAGEIF(Datos!$J$2:$J$601,J4,Datos!$M$2:$M$601),0) -> 181249.86
B5: Febrero | C5: =COUNTIF(Datos!$G$2:$G$601,B5) -> 49 | D5: =IFERROR(AVERAGEIF(Datos!$G$2:$G$601,B5,Datos!$M$2:$M$601),0) -> 188636.12 | F5: 25-34 | G5: =COUNTIF(Datos!$S$2:$S$601,F5) -> 120 | H5: =IFERROR(AVERAGEIF(Datos!$S$2:$S$601,F5,Datos!$M$2:$M$601),0) -> 173849.32 | J5: Cartago | K5: =COUNTIF(Datos!$J$2:$J$601,J5) -> 77 | L5: =IFERROR(AVERAGEIF(Datos!$J$2:$J$601,J5,Datos!$M$2:$M$601),0) -> 162808.27
B6: Marzo | C6: =COUNTIF(Datos!$G$2:$G$601,B6) -> 37 | D6: =IFERROR(AVERAGEIF(Datos!$G$2:$G$601,B6,Datos!$M$2:$M$601),0) -> 188493 | F6: 35-44 | G6: =COUNTIF(Datos!$S$2:$S$601,F6) -> 137 | H6: =IFERROR(AVERAGEIF(Datos!$S$2:$S$601,F6,Datos!$M$2:$M$601),0) -> 168954.58 | J6: Guanacaste | K6: =COUNTIF(Datos!$J$2:$J$601,J6) -> 94 | L6: =IFERROR(AVERAGEIF(Datos!$J$2:$J$601,J6,Datos!$M$2:$M$601),0) -> 185151.87
B7: Abril | C7: =COUNTIF(Datos!$G$2:$G$601,B7) -> 37 | D7: =IFERROR(AVERAGEIF(Datos!$G$2:$G$601,B7,Datos!$M$2:$M$601),0) -> 199646.73 | F7: 45-54 | G7: =COUNTIF(Datos!$S$2:$S$601,F7) -> 122 | H7: =IFERROR(AVERAGEIF(Datos!$S$2:$S$601,F7,Datos!$M$2:$M$601),0) -> 183341.79 | J7: Heredia | K7: =COUNTIF(Datos!$J$2:$J$601,J7) -> 78 | L7: =IFERROR(AVERAGEIF(Datos!$J$2:$J$601,J7,Datos!$M$2:$M$601),0) -> 185109.03
B8: Mayo | C8: =COUNTIF(Datos!$G$2:$G$601,B8) -> 55 | D8: =IFERROR(AVERAGEIF(Datos!$G$2:$G$601,B8,Datos!$M$2:$M$601),0) -> 182785.05 | F8: 55-65 | G8: =COUNTIF(Datos!$S$2:$S$601,F8) -> 151 | H8: =IFERROR(AVERAGEIF(Datos!$S$2:$S$601,F8,Datos!$M$2:$M$601),0) -> 177767.6 | J8: Limón | K8: =COUNTIF(Datos!$J$2:$J$601,J8) -> 88 | L8: =IFERROR(AVERAGEIF(Datos!$J$2:$J$601,J8,Datos!$M$2:$M$601),0) -> 181292.51
B9: Junio | C9: =COUNTIF(Datos!$G$2:$G$601,B9) -> 56 | D9: =IFERROR(AVERAGEIF(Datos!$G$2:$G$601,B9,Datos!$M$2:$M$601),0) -> 172604.62 | J9: Puntarenas | K9: =COUNTIF(Datos!$J$2:$J$601,J9) -> 89 | L9: =IFERROR(AVERAGEIF(Datos!$J$2:$J$601,J9,Datos!$M$2:$M$601),0) -> 152216.54
B10: Julio | C10: =COUNTIF(Datos!$G$2:$G$601,B10) -> 42 | D10: =IFERROR(AVERAGEIF(Datos!$G$2:$G$601,B10,Datos!$M$2:$M$601),0) -> 163917.88 | J10: San José | K10: =COUNTIF(Datos!$J$2:$J$601,J10) -> 94 | L10: =IFERROR(AVERAGEIF(Datos!$J$2:$J$601,J10,Datos!$M$2:$M$601),0) -> 170188.81
B11: Agosto | C11: =COUNTIF(Datos!$G$2:$G$601,B11) -> 59 | D11: =IFERROR(AVERAGEIF(Datos!$G$2:$G$601,B11,Datos!$M$2:$M$601),0) -> 171464.93
B12: Septiembre | C12: =COUNTIF(Datos!$G$2:$G$601,B12) -> 51 | D12: =IFERROR(AVERAGEIF(Datos!$G$2:$G$601,B12,Datos!$M$2:$M$601),0) -> 169909.92
B13: Octubre | C13: =COUNTIF(Datos!$G$2:$G$601,B13) -> 51 | D13: =IFERROR(AVERAGEIF(Datos!$G$2:$G$601,B13,Datos!$M$2:$M$601),0) -> 157084.88
B14: Noviembre | C14: =COUNTIF(Datos!$G$2:$G$601,B14) -> 60 | D14: =IFERROR(AVERAGEIF(Datos!$G$2:$G$601,B14,Datos!$M$2:$M$601),0) -> 157911.78
B15: Diciembre | C15: =COUNTIF(Datos!$G$2:$G$601,B15) -> 58 | D15: =IFERROR(AVERAGEIF(Datos!$G$2:$G$601,B15,Datos!$M$2:$M$601),0) -> 170304.38
B20: 4. Conducta de gasto | F20: 5. Frecuencia de compra | J20: 6. Momento del día preferido
B21: Categoría | C21: Cantidad | D21: Gasto Prom. (₡) | F21: Categoría | G21: Cantidad | J21: Categoría | K21: Cantidad | L21: Gasto Prom. (₡)
B22: Planificador | C22: =COUNTIF(Datos!$L$2:$L$601,B22) -> 134 | D22: =IFERROR(AVERAGEIF(Datos!$L$2:$L$601,B22,Datos!$M$2:$M$601),0) -> 182280.91 | F22: Diaria | G22: =COUNTIF(Datos!$N$2:$N$601,F22) -> 124 | J22: Mañana | K22: =COUNTIF(Datos!$O$2:$O$601,J22) -> 200 | L22: =IFERROR(AVERAGEIF(Datos!$O$2:$O$601,J22,Datos!$M$2:$M$601),0) -> 171906.64
B23: Moderado | C23: =COUNTIF(Datos!$L$2:$L$601,B23) -> 126 | D23: =IFERROR(AVERAGEIF(Datos!$L$2:$L$601,B23,Datos!$M$2:$M$601),0) -> 186101.78 | F23: Semanal | G23: =COUNTIF(Datos!$N$2:$N$601,F23) -> 126 | J23: Tarde | K23: =COUNTIF(Datos!$O$2:$O$601,J23) -> 208 | L23: =IFERROR(AVERAGEIF(Datos!$O$2:$O$601,J23,Datos!$M$2:$M$601),0) -> 180723.89
B24: Gastador impulsivo | C24: =COUNTIF(Datos!$L$2:$L$601,B24) -> 118 | D24: =IFERROR(AVERAGEIF(Datos!$L$2:$L$601,B24,Datos!$M$2:$M$601),0) -> 169112.11 | F24: Quincenal | G24: =COUNTIF(Datos!$N$2:$N$601,F24) -> 114 | J24: Noche | K24: =COUNTIF(Datos!$O$2:$O$601,J24) -> 192 | L24: =IFERROR(AVERAGEIF(Datos!$O$2:$O$601,J24,Datos!$M$2:$M$601),0) -> 168780.57
B25: Ahorrador | C25: =COUNTIF(Datos!$L$2:$L$601,B25) -> 114 | D25: =IFERROR(AVERAGEIF(Datos!$L$2:$L$601,B25,Datos!$M$2:$M$601),0) -> 156390.27 | F25: Mensual | G25: =COUNTIF(Datos!$N$2:$N$601,F25) -> 110
B26: Gastador en ocasiones especiales | C26: =COUNTIF(Datos!$L$2:$L$601,B26) -> 108 | D26: =IFERROR(AVERAGEIF(Datos!$L$2:$L$601,B26,Datos!$M$2:$M$601),0) -> 173329.45 | F26: Ocasional | G26: =COUNTIF(Datos!$N$2:$N$601,F26) -> 126
B31: 7. Categoría de preferencia | F31: 8. Top 12 marcas preferidas | J31: 9. Método de pago
B32: Categoría | C32: Cantidad | D32: Gasto Prom. (₡) | F32: Categoría | G32: Cantidad | J32: Categoría | K32: Cantidad | L32: Gasto Prom. (₡)
B33: Educación | C33: =COUNTIF(Datos!$P$2:$P$601,B33) -> 75 | D33: =IFERROR(AVERAGEIF(Datos!$P$2:$P$601,B33,Datos!$M$2:$M$601),0) -> 170102.51 | F33: Adidas | G33: =COUNTIF(Datos!$Q$2:$Q$601,F33) -> 27 | J33: PayPal | K33: =COUNTIF(Datos!$R$2:$R$601,J33) -> 128 | L33: =IFERROR(AVERAGEIF(Datos!$R$2:$R$601,J33,Datos!$M$2:$M$601),0) -> 180201.82
B34: Moda y ropa | C34: =COUNTIF(Datos!$P$2:$P$601,B34) -> 74 | D34: =IFERROR(AVERAGEIF(Datos!$P$2:$P$601,B34,Datos!$M$2:$M$601),0) -> 187896.41 | F34: UNED | G34: =COUNTIF(Datos!$Q$2:$Q$601,F34) -> 23 | J34: Tarjeta de débito | K34: =COUNTIF(Datos!$R$2:$R$601,J34) -> 125 | L34: =IFERROR(AVERAGEIF(Datos!$R$2:$R$601,J34,Datos!$M$2:$M$601),0) -> 185016.22
B35: Comida y restaurantes | C35: =COUNTIF(Datos!$P$2:$P$601,B35) -> 69 | D35: =IFERROR(AVERAGEIF(Datos!$P$2:$P$601,B35,Datos!$M$2:$M$601),0) -> 166070.65 | F35: Nike | G35: =COUNTIF(Datos!$Q$2:$Q$601,F35) -> 22 | J35: SINPE Móvil | K35: =COUNTIF(Datos!$R$2:$R$601,J35) -> 125 | L35: =IFERROR(AVERAGEIF(Datos!$R$2:$R$601,J35,Datos!$M$2:$M$601),0) -> 171755.47
B36: Deportes y fitness | C36: =COUNTIF(Datos!$P$2:$P$601,B36) -> 62 | D36: =IFERROR(AVERAGEIF(Datos!$P$2:$P$601,B36,Datos!$M$2:$M$601),0) -> 189283.82 | F36: McDonald's | G36: =COUNTIF(Datos!$Q$2:$Q$601,F36) -> 19 | J36: Efectivo | K36: =COUNTIF(Datos!$R$2:$R$601,J36) -> 119 | L36: =IFERROR(AVERAGEIF(Datos!$R$2:$R$601,J36,Datos!$M$2:$M$601),0) -> 162310.02
B37: Tecnología | C37: =COUNTIF(Datos!$P$2:$P$601,B37) -> 59 | D37: =IFERROR(AVERAGEIF(Datos!$P$2:$P$601,B37,Datos!$M$2:$M$601),0) -> 182216.8 | F37: H&M | G37: =COUNTIF(Datos!$Q$2:$Q$601,F37) -> 17 | J37: Tarjeta de crédito | K37: =COUNTIF(Datos!$R$2:$R$601,J37) -> 103 | L37: =IFERROR(AVERAGEIF(Datos!$R$2:$R$601,J37,Datos!$M$2:$M$601),0) -> 168937.67
B38: Belleza y cuidado personal | C38: =COUNTIF(Datos!$P$2:$P$601,B38) -> 59 | D38: =IFERROR(AVERAGEIF(Datos!$P$2:$P$601,B38,Datos!$M$2:$M$601),0) -> 175846.63 | F38: Smart Fit | G38: =COUNTIF(Datos!$Q$2:$Q$601,F38) -> 17
B39: Hogar y decoración | C39: =COUNTIF(Datos!$P$2:$P$601,B39) -> 54 | D39: =IFERROR(AVERAGEIF(Datos!$P$2:$P$601,B39,Datos!$M$2:$M$601),0) -> 147853.93 | F39: UCR | G39: =COUNTIF(Datos!$Q$2:$Q$601,F39) -> 16
B40: Viajes | C40: =COUNTIF(Datos!$P$2:$P$601,B40) -> 51 | D40: =IFERROR(AVERAGEIF(Datos!$P$2:$P$601,B40,Datos!$M$2:$M$601),0) -> 186938.49 | F40: Zara | G40: =COUNTIF(Datos!$Q$2:$Q$601,F40) -> 15
B41: Videojuegos | C41: =COUNTIF(Datos!$P$2:$P$601,B41) -> 49 | D41: =IFERROR(AVERAGEIF(Datos!$P$2:$P$601,B41,Datos!$M$2:$M$601),0) -> 169513.84 | F41: Disney+ | G41: =COUNTIF(Datos!$Q$2:$Q$601,F41) -> 15
B42: Entretenimiento/streaming | C42: =COUNTIF(Datos!$P$2:$P$601,B42) -> 48 | D42: =IFERROR(AVERAGEIF(Datos!$P$2:$P$601,B42,Datos!$M$2:$M$601),0) -> 157737.04 | F42: Natura | G42: =COUNTIF(Datos!$Q$2:$Q$601,F42) -> 15
F43: Aldo | G43: =COUNTIF(Datos!$Q$2:$Q$601,F43) -> 14
F44: Motorola | G44: =COUNTIF(Datos!$Q$2:$Q$601,F44) -> 14
B45: 10. Signo zodiacal | F45: 11. Género
B46: Categoría | C46: Cantidad | F46: Categoría | G46: Cantidad | H46: Gasto Prom. (₡)
B47: Sagitario | C47: =COUNTIF(Datos!$I$2:$I$601,B47) -> 62 | F47: Femenino | G47: =COUNTIF(Datos!$E$2:$E$601,F47) -> 313 | H47: =IFERROR(AVERAGEIF(Datos!$E$2:$E$601,F47,Datos!$M$2:$M$601),0) -> 175479.17
B48: Virgo | C48: =COUNTIF(Datos!$I$2:$I$601,B48) -> 58 | F48: Masculino | G48: =COUNTIF(Datos!$E$2:$E$601,F48) -> 287 | H48: =IFERROR(AVERAGEIF(Datos!$E$2:$E$601,F48,Datos!$M$2:$M$601),0) -> 172309.36
B49: Géminis | C49: =COUNTIF(Datos!$I$2:$I$601,B49) -> 56
...
